Workbook

Sheet Client_Summary
A1: CLIENT PACKAGE COMPLETION & PROBABILITY DASHBOARD
A2: Master Register Overview & Probability of Package Over Date
A4: S.No. | B4: Reg. Date | C4: Client Name | D4: Package Status | E4: Total Duration (Mins/Value) | F4: Consumed (Mins/Value) | G4: % Completed | H4: Prob. Package Over Date
A5: 1 | B5: 09/06/2025 | C5: Mr. Subhajit Guha | D5: =IF(G5>=1, "OVER", IF(F5=0, "NOT STARTED", "ACTIVE")) -> ACTIVE | E5: 900 | F5: =Subhajit_Guha!E13 -> 510 | G5: =F5/E5 -> 56.7% | H5: =Subhajit_Guha!H13 -> 56.7%
A6: 2 | B6: 14/06/2025 | C6: Mr. Subrata Mandal (New Pkg Active) | D6: =IF(G6>=1, "OVER", IF(F6=0, "NOT STARTED", "ACTIVE")) -> ACTIVE | E6: 2580 | F6: =Subrata_Mandal!E27 -> 1,710 | G6: =F6/E6 -> 66.3% | H6: =Subrata_Mandal!H27 -> 66.3%
A7: 3 | B7: 17/06/2025 | C7: Miss Rituparna Banerjee | D7: =IF(G7>=1, "OVER", IF(F7=0, "NOT STARTED", "ACTIVE")) -> ACTIVE | E7: 300 | F7: =Rituparna_Banerjee!E6 -> 180 | G7: =F7/E7 -> 60.0% | H7: =Rituparna_Banerjee!H6 -> 60.0%
A8: 4 | B8: 20/06/2025 | C8: Mr. Murali Panikar | D8: =IF(G8>=1, "OVER", IF(F8=0, "NOT STARTED", "ACTIVE")) -> OVER | E8: 360 | F8: =Murali_Panikar!E9 -> 410 | G8: =F8/E8 -> 113.9% | H8: =Murali_Panikar!H9 -> 100.0% (Package Over)
A9: 5 | B9: 20/06/2025 | C9: Mr. Supratim Roy | D9: =IF(G9>=1, "OVER", IF(F9=0, "NOT STARTED", "ACTIVE")) -> OVER | E9: 480 | F9: =Supratim_Roy!E12 -> 720 | G9: =F9/E9 -> 150.0% | H9: =Supratim_Roy!H12 -> 100.0% (Package Over)
A10: 6 | B10: 03/07/2025 | C10: Miss Anindita Ghose | D10: =IF(G10>=1, "OVER", IF(F10=0, "NOT STARTED", "ACTIVE")) -> NOT STARTED | E10: 300 | F10: =Anindita_Ghose!E5 -> 0 | G10: =F10/E10 -> 0.0% | H10: =Anindita_Ghose!H5 -> 0.0%
A11: 7 | B11: 14/07/2025 | C11: Mr. Anand Mehta | D11: =IF(G11>=1, "OVER", IF(F11=0, "NOT STARTED", "ACTIVE")) -> OVER | E11: 1200 | F11: =Anand_Mehta!E23 -> 1,200 | G11: =F11/E11 -> 100.0% | H11: =Anand_Mehta!H23 -> 100.0% (Package Over)
A12: 8 | B12: 18/07/2025 | C12: Mr. Subhabrata Roy (Paid 20k for 30 hrs) | D12: =IF(G12>=1, "OVER", IF(F12=0, "NOT STARTED", "ACTIVE")) -> ACTIVE | E12: 1800 | F12: =Subhabrata!E17 -> 1,290 | G12: =F12/E12 -> 71.7% | H12: =Subhabrata!H17 -> 71.7%
A13: 9 | B13: 20/07/2025 | C13: Mr. Sushanta Bhattacharya (Paid 5k for 20 hr) | D13: =IF(G13>=1, "OVER", IF(F13=0, "NOT STARTED", "ACTIVE")) -> NOT STARTED | E13: 6000 | F13: =Sushanta!E5 -> 0 | G13: =F13/E13 -> 0.0% | H13: =Sushanta!H5 -> 0.0%
A14: 10 | B14: 22/07/2025 | C14: Mr. Anand Poddar | D14: =IF(G14>=1, "OVER", IF(F14=0, "NOT STARTED", "ACTIVE")) -> OVER | E14: 420 | F14: =Anand_Poddar!E12 -> 420 | G14: =F14/E14 -> 100.0% | H14: =Anand_Poddar!H12 -> 100.0% (Package Over)
A15: 11 | B15: 23/07/2025 | C15: Mr. Debabrata Dey | D15: =IF(G15>=1, "OVER", IF(F15=0, "NOT STARTED", "ACTIVE")) -> OVER | E15: 7000 | F15: =Debabrata_Dey!E8 -> 7,000 | G15: =F15/E15 -> 100.0% | H15: =Debabrata_Dey!H8 -> 100.0% (Package Over)
A16: 12 | B16: 07/08/2025 | C16: Madhumita Chatterjee / Dey (8240366754 - Paid 5k for 7h + 5k for 7k x2) | D16: =IF(G16>=1, "OVER", IF(F16=0, "NOT STARTED", "ACTIVE")) -> ACTIVE | E16: 14420 | F16: =Madhumita_Chatterjee!E21 -> 9,420 | G16: =F16/E16 -> 65.3% | H16: =Madhumita_Chatterjee!H21 -> 65.3%
A17: 13 | B17: 13/08/2025 | C17: Mr. Randhir Paul (Paid 5k for 10 Sessions x2 New Pkgs) | D17: =IF(G17>=1, "OVER", IF(F17=0, "NOT STARTED", "ACTIVE")) -> ACTIVE | E17: 2400 | F17: =Randhir_Paul!E28 -> 1,800 | G17: =F17/E17 -> 75.0% | H17: =Randhir_Paul!H28 -> 75.0%
A18: 14 | B18: 14/08/2025 | C18: Mrs. Manish Jaiswal / Pankaj Jaisneel (Merged Pkg) | D18: =IF(G18>=1, "OVER", IF(F18=0, "NOT STARTED", "ACTIVE")) -> ACTIVE | E18: 9200 | F18: =Manish_Jaiswal!E21 -> 9,170 | G18: =F18/E18 -> 99.7% | H18: =Manish_Jaiswal!H21 -> 99.7%
A19: 15 | B19: 15/08/2025 | C19: Dr. R.C. Yadav (Paid 5k for 10 hrs & Self + 2 New Pkgs) | D19: =IF(G19>=1, "OVER", IF(F19=0, "NOT STARTED", "ACTIVE")) -> ACTIVE | E19: 2400 | F19: =RC_Yadav!E41 -> 2,280 | G19: =F19/E19 -> 95.0% | H19: =RC_Yadav!H41 -> 95.0%
A20: 16 | B20: 18/08/2025 | C20: Mr. Indrajit Basak (Paid 5k for 8 hrs - New Pkg) | D20: =IF(G20>=1, "OVER", IF(F20=0, "NOT STARTED", "ACTIVE")) -> ACTIVE | E20: 960 | F20: =Indrajit_Basak!E17 -> 750 | G20: =F20/E20 -> 78.1% | H20: =Indrajit_Basak!H17 -> 78.1%
A21: 17 | B21: 20/08/2025 | C21: Mr. Sumeet (10k Paid for 15 hrs + 10k Paid for 15k Value) | D21: =IF(G21>=1, "OVER", IF(F21=0, "NOT STARTED", "ACTIVE")) -> ACTIVE | E21: 14700 | F21: =Sumeet!E12 -> 510 | G21: =F21/E21 -> 3.5% | H21: =Sumeet!H12 -> 3.5%
A22: 18 | B22: 24/08/2025 | C22: Miss Samapti Roy (Paid 5k for 7 hrs & 8 hrs) | D22: =IF(G22>=1, "OVER", IF(F22=0, "NOT STARTED", "ACTIVE")) -> OVER | E22: 900 | F22: =Samapti_Roy!E19 -> 900 | G22: =F22/E22 -> 100.0% | H22: =Samapti_Roy!H19 -> 100.0% (Package Over)
A23: 19 | B23: 08/09/2025 | C23: Mr. M.K. Sarkar (Anniversary Special Offer) | D23: =IF(G23>=1, "OVER", IF(F23=0, "NOT STARTED", "ACTIVE")) -> ACTIVE | E23: 1200 | F23: =MK_Sarkar!E21 -> 900 | G23: =F23/E23 -> 75.0% | H23: =MK_Sarkar!H21 -> 75.0%
A24: 20 | B24: 26/09/2025 | C24: Mrs. Komal Sinha (Pooja Offer - 5k for 6 Sessions) | D24: =IF(G24>=1, "OVER", IF(F24=0, "NOT STARTED", "ACTIVE")) -> OVER | E24: 8650 | F24: =Komal_Sinha!E12 -> 8,650 | G24: =F24/E24 -> 100.0% | H24: =Komal_Sinha!H12 -> 100.0% (Package Over)
A25: 21 | B25: 08/10/2025 | C25: J. Mehta (9830111676 - Paid 10k for 14 hrs) | D25: =IF(G25>=1, "OVER", IF(F25=0, "NOT STARTED", "ACTIVE")) -> ACTIVE | E25: 840 | F25: =J_Mehta!E14 -> 810 | G25: =F25/E25 -> 96.4% | H25: =J_Mehta!H14 -> 96.4%
A26: 22 | B26: 09/10/2025 | C26: Mr. Utpal Chowdhury (Paid 20k for 25k) | D26: =IF(G26>=1, "OVER", IF(F26=0, "NOT STARTED", "ACTIVE")) -> ACTIVE | E26: 26900 | F26: =Utpal_Chowdhury!E10 -> 24,900 | G26: =F26/E26 -> 92.6% | H26: =Utpal_Chowdhury!H10 -> 92.6%
A27: 23 | B27: 11/10/2025 | C27: Mr. Bijan Roy Chowdhury (Paid 5k for 450m + Paid 5k for 510m) | D27: =IF(G27>=1, "OVER", IF(F27=0, "NOT STARTED", "ACTIVE")) -> OVER | E27: 960 | F27: =Bijan_Roy_Chowdhury!E15 -> 960 | G27: =F27/E27 -> 100.0% | H27: =Bijan_Roy_Chowdhury!H15 -> 100.0% (Package Over)
A28: 24 | B28: 11/10/2025 | C28: Mr. Sanjit Biswas (Paid 5k for 7k + 1 Year Anniversary Offer) | D28: =IF(G28>=1, "OVER", IF(F28=0, "NOT STARTED", "ACTIVE")) -> ACTIVE | E28: 14710 | F28: =Sanjit_Biswas!E14 -> 14,320 | G28: =F28/E28 -> 97.3% | H28: =Sanjit_Biswas!H14 -> 97.3%
A29: 25 | B29: 17/10/2025 | C29: Mrs. Rakhi Senapati (Paid 5k for 10 Sessions) | D29: =IF(G29>=1, "OVER", IF(F29=0, "NOT STARTED", "ACTIVE")) -> ACTIVE | E29: 600 | F29: =Rakhi_Senapati!E6 -> 120 | G29: =F29/E29 -> 20.0% | H29: =Rakhi_Senapati!H6 -> 20.0%
A30: 26 | B30: 19/10/2025 | C30: Miss Monali Sengupta (9163526861 - 5k for 7k Pkg x2) | D30: =IF(G30>=1, "OVER", IF(F30=0, "NOT STARTED", "ACTIVE")) -> ACTIVE | E30: 14000 | F30: =Monali_Sengupta!E11 -> 6,470 | G30: =F30/E30 -> 46.2% | H30: =Monali_Sengupta!H11 -> 46.2%
A31: 27 | B31: 21/10/2025 | C31: Mr. Palas Sarkar (Paid Total 5k for 10 Hours) | D31: =IF(G31>=1, "OVER", IF(F31=0, "NOT STARTED", "ACTIVE")) -> OVER | E31: 600 | F31: =Palas_Sarkar!E14 -> 600 | G31: =F31/E31 -> 100.0% | H31: =Palas_Sarkar!H14 -> 100.0% (Package Over)
A32: 28 | B32: 25/10/2025 | C32: Mr. Avisek Ram (Paid 5k for 9 Hours) | D32: =IF(G32>=1, "OVER", IF(F32=0, "NOT STARTED", "ACTIVE")) -> OVER | E32: 540 | F32: =Avisek_Ram!E13 -> 540 | G32: =F32/E32 -> 100.0% | H32: =Avisek_Ram!H13 -> 100.0% (Package Over)
A33: 29 | B33: 26/10/2025 | C33: Mr. Dinesh Kumar (Paid 5k for 10 Sessions / 600 Mins) | D33: =IF(G33>=1, "OVER", IF(F33=0, "NOT STARTED", "ACTIVE")) -> OVER | E33: 600 | F33: =Dinesh_Kumar!E14 -> 600 | G33: =F33/E33 -> 100.0% | H33: =Dinesh_Kumar!H14 -> 100.0% (Package Over)
A34: 30 | B34: 27/10/2025 | C34: Mr. Subhendu Chatterjee (Paid 5k for 8 Sessions / 480 Mins) | D34: =IF(G34>=1, "OVER", IF(F34=0, "NOT STARTED", "ACTIVE")) -> ACTIVE | E34: 480 | F34: =Subhendu_Chatterjee!E9 -> 300 | G34: =F34/E34 -> 62.5% | H34: =Subhendu_Chatterjee!H9 -> 62.5%
A35: 31 | B35: 28/10/2025 | C35: Miss Tripti Karmakar (Paid 5k for 8 Sessions / 480 Mins) | D35: =IF(G35>=1, "OVER", IF(F35=0, "NOT STARTED", "ACTIVE")) -> ACTIVE | E35: 480 | F35: =Tripti_Karmakar!E8 -> 240 | G35: =F35/E35 -> 50.0% | H35: =Tripti_Karmakar!H8 -> 50.0%
A36: 32 | B36: 04/11/2025 | C36: Mr. Shayamal Das (7003913586 - Paid 5k for 11 Hours) | D36: =IF(G36>=1, "OVER", IF(F36=0, "NOT STARTED", "ACTIVE")) -> ACTIVE | E36: 660 | F36: =Shayamal_Das!E7 -> 240 | G36: =F36/E36 -> 36.4% | H36: =Shayamal_Das!H7 -> 36.4%
A37: 33 | B37: 07/11/2025 | C37: Mr. Subhandip Das (9831594967 / 9831594967 - Paid 5k for 8 Sessions) | D37: =IF(G37>=1, "OVER", IF(F37=0, "NOT STARTED", "ACTIVE")) -> OVER | E37: 480 | F37: =Subhandip_Das!E11 -> 480 | G37: =F37/E37 -> 100.0% | H37: =Subhandip_Das!H11 -> 100.0% (Package Over)
A38: 34 | B38: 07/11/2025 | C38: Mr. Vivek Partwani (Paid 5k for 7k Package) | D38: =IF(G38>=1, "OVER", IF(F38=0, "NOT STARTED", "ACTIVE")) -> ACTIVE | E38: 7000 | F38: =Vivek_Partwani!E7 -> 2,850 | G38: =F38/E38 -> 40.7% | H38: =Vivek_Partwani!H7 -> 40.7%
A39: 35 | B39: 09/11/2025 | C39: Mr. Vivek Gupta (9883284012 - Paid 5k for 7k x2 Pkgs) | D39: =IF(G39>=1, "OVER", IF(F39=0, "NOT STARTED", "ACTIVE")) -> ACTIVE | E39: 14000 | F39: =Vivek_Gupta!E8 -> 7,000 | G39: =F39/E39 -> 50.0% | H39: =Vivek_Gupta!H8 -> 50.0%
A40: 36 | B40: 10/11/2025 | C40: Mr. Kishor Kumar Chatterjee (Paid 5k for 8 Hours x2 Pkgs) | D40: =IF(G40>=1, "OVER", IF(F40=0, "NOT STARTED", "ACTIVE")) -> ACTIVE | E40: 960 | F40: =Kishor_Kumar_Chatterjee!E19 -> 930 | G40: =F40/E40 -> 96.9% | H40: =Kishor_Kumar_Chatterjee!H19 -> 96.9%

Sheet Subhajit_Guha
A1: CLIENT SESSION TRACKER: MR. SUBHAJIT GUHA
A2: Start Date: 09/06/2025 | Package Details: Paid 10k for 15 Hours | Total Package Capacity: 900 Mins
A4: Session No. | B4: Session Date | C4: Duration (Mins/Value) | D4: Therapist / Details | E4: Cumulative Usage | F4: Remaining Balance | G4: % Package Consumed | H4: Prob. Package Over Date
A5: 1 | B5: 09/06/2025 | C5: 60 | D5: Ritvika | E5: =C5 -> 60 | F5: =900-E5 -> 840 | G5: =E5/900 -> 6.7% | H5: =IF(G5>=1, "100.0% (Package Over)", TEXT(MIN(G5*100, 99.9), "0.0") & "%") -> 6.7%
A6: 2 | B6: 24/06/2025 | C6: 60 | D6: Ritvika | E6: =E5+C6 -> 120 | F6: =900-E6 -> 780 | G6: =E6/900 -> 13.3% | H6: =IF(G6>=1, "100.0% (Package Over)", TEXT(MIN(G6*100, 99.9), "0.0") & "%") -> 13.3%
A7: 3 | B7: 04/08/2025 | C7: 60 | D7: Soma | E7: =E6+C7 -> 180 | F7: =900-E7 -> 720 | G7: =E7/900 -> 20.0% | H7: =IF(G7>=1, "100.0% (Package Over)", TEXT(MIN(G7*100, 99.9), "0.0") & "%") -> 20.0%
A8: 4 | B8: 14/10/2025 | C8: 60 | D8: Ritika | E8: =E7+C8 -> 240 | F8: =900-E8 -> 660 | G8: =E8/900 -> 26.7% | H8: =IF(G8>=1, "100.0% (Package Over)", TEXT(MIN(G8*100, 99.9), "0.0") & "%") -> 26.7%
A9: 5 | B9: 11/11/2025 | C9: 60 | D9: Sneha | E9: =E8+C9 -> 300 | F9: =900-E9 -> 600 | G9: =E9/900 -> 33.3% | H9: =IF(G9>=1, "100.0% (Package Over)", TEXT(MIN(G9*100, 99.9), "0.0") & "%") -> 33.3%
A10: 6 | B10: 24/12/2025 | C10: 30 | D10: Ritika | E10: =E9+C10 -> 330 | F10: =900-E10 -> 570 | G10: =E10/900 -> 36.7% | H10: =IF(G10>=1, "100.0% (Package Over)", TEXT(MIN(G10*100, 99.9), "0.0") & "%") -> 36.7%
A11: 7 | B11: 01/01/2026 | C11: 90 | D11: Ritika | E11: =E10+C11 -> 420 | F11: =900-E11 -> 480 | G11: =E11/900 -> 46.7% | H11: =IF(G11>=1, "100.0% (Package Over)", TEXT(MIN(G11*100, 99.9), "0.0") & "%") -> 46.7%
A12: 8 | B12: 30/01/2026 | C12: 60 | D12: Sheelam | E12: =E11+C12 -> 480 | F12: =900-E12 -> 420 | G12: =E12/900 -> 53.3% | H12: =IF(G12>=1, "100.0% (Package Over)", TEXT(MIN(G12*100, 99.9), "0.0") & "%") -> 53.3%
A13: 9 | B13: 24/04/2026 | C13: 30 | D13: Daliya | E13: =E12+C13 -> 510 | F13: =900-E13 -> 390 | G13: =E13/900 -> 56.7% | H13: =IF(G13>=1, "100.0% (Package Over)", TEXT(MIN(G13*100, 99.9), "0.0") & "%") -> 56.7%

Sheet Subrata_Mandal
A1: CLIENT SESSION TRACKER: MR. SUBRATA MANDAL
A2: Start Date: 14/06/2025 | Package Details: Pkg 1 (900m) + Pkg 2 (420m) + Pkg 3 (420m) + Pkg 4 (420m) + Pkg 5 (420m) | Total Package Capacity: 2580 Mins
A4: Session No. | B4: Session Date | C4: Duration (Mins/Value) | D4: Therapist / Details | E4: Cumulative Usage | F4: Remaining Balance | G4: % Package Consumed | H4: Prob. Package Over Date
A5: 1 | B5: 14/06/2025 | C5: 60 | D5: Riya (Pkg 1) | E5: =C5 -> 60 | F5: =2580-E5 -> 2520 | G5: =E5/2580 -> 2.3% | H5: =IF(G5>=1, "100.0% (Package Over)", TEXT(MIN(G5*100, 99.9), "0.0") & "%") -> 2.3%
A6: 2 | B6: 16/06/2025 | C6: 90 | D6: Riya | E6: =E5+C6 -> 150 | F6: =2580-E6 -> 2430 | G6: =E6/2580 -> 5.8% | H6: =IF(G6>=1, "100.0% (Package Over)", TEXT(MIN(G6*100, 99.9), "0.0") & "%") -> 5.8%
A7: 3 | B7: 21/06/2025 | C7: 120 | D7: Ritika | E7: =E6+C7 -> 270 | F7: =2580-E7 -> 2310 | G7: =E7/2580 -> 10.5% | H7: =IF(G7>=1, "100.0% (Package Over)", TEXT(MIN(G7*100, 99.9), "0.0") & "%") -> 10.5%
A8: 4 | B8: 23/06/2025 | C8: 60 | D8: Soma | E8: =E7+C8 -> 330 | F8: =2580-E8 -> 2250 | G8: =E8/2580 -> 12.8% | H8: =IF(G8>=1, "100.0% (Package Over)", TEXT(MIN(G8*100, 99.9), "0.0") & "%") -> 12.8%
A9: 5 | B9: 24/06/2025 | C9: 90 | D9: Ritika | E9: =E8+C9 -> 420 | F9: =2580-E9 -> 2160 | G9: =E9/2580 -> 16.3% | H9: =IF(G9>=1, "100.0% (Package Over)", TEXT(MIN(G9*100, 99.9), "0.0") & "%") -> 16.3%
A10: 6 | B10: 25/06/2025 | C10: 90 | D10: Soma | E10: =E9+C10 -> 510 | F10: =2580-E10 -> 2070 | G10: =E10/2580 -> 19.8% | H10: =IF(G10>=1, "100.0% (Package Over)", TEXT(MIN(G10*100, 99.9), "0.0") & "%") -> 19.8%
A11: 7 | B11: 01/07/2025 | C11: 120 | D11: Ritika | E11: =E10+C11 -> 630 | F11: =2580-E11 -> 1950 | G11: =E11/2580 -> 24.4% | H11: =IF(G11>=1, "100.0% (Package Over)", TEXT(MIN(G11*100, 99.9), "0.0") & "%") -> 24.4%
A12: 8 | B12: 02/07/2025 | C12: 60 | D12: Ritika | E12: =E11+C12 -> 690 | F12: =2580-E12 -> 1890 | G12: =E12/2580 -> 26.7% | H12: =IF(G12>=1, "100.0% (Package Over)", TEXT(MIN(G12*100, 99.9), "0.0") & "%") -> 26.7%
A13: 9 | B13: 11/07/2025 | C13: 120 | D13: Ritika | E13: =E12+C13 -> 810 | F13: =2580-E13 -> 1770 | G13: =E13/2580 -> 31.4% | H13: =IF(G13>=1, "100.0% (Package Over)", TEXT(MIN(G13*100, 99.9), "0.0") & "%") -> 31.4%
A14: 10 | B14: 18/07/2025 | C14: 60 | D14: Smrita | E14: =E13+C14 -> 870 | F14: =2580-E14 -> 1710 | G14: =E14/2580 -> 33.7% | H14: =IF(G14>=1, "100.0% (Package Over)", TEXT(MIN(G14*100, 99.9), "0.0") & "%") -> 33.7%
A15: 11 | B15: 21/08/2025 | C15: 30 | D15: Soma (Pkg 2) | E15: =E14+C15 -> 900 | F15: =2580-E15 -> 1680 | G15: =E15/2580 -> 34.9% | H15: =IF(G15>=1, "100.0% (Package Over)", TEXT(MIN(G15*100, 99.9), "0.0") & "%") -> 34.9%
A16: 12 | B16: 27/08/2025 | C16: 60 | D16: Barsha | E16: =E15+C16 -> 960 | F16: =2580-E16 -> 1620 | G16: =E16/2580 -> 37.2% | H16: =IF(G16>=1, "100.0% (Package Over)", TEXT(MIN(G16*100, 99.9), "0.0") & "%") -> 37.2%
A17: 13 | B17: 11/09/2025 | C17: 90 | D17: Suparna | E17: =E16+C17 -> 1050 | F17: =2580-E17 -> 1530 | G17: =E17/2580 -> 40.7% | H17: =IF(G17>=1, "100.0% (Package Over)", TEXT(MIN(G17*100, 99.9), "0.0") & "%") -> 40.7%
... A27: 23 | B27: 01/07/2026 | C27: 60 | D27: Bipasha (FHNS - Pkg 3 Over) | E27: =E26+C27 -> 1710 | F27: =2580-E27 -> 870 | G27: =E27/2580 -> 66.3% | H27: =IF(G27>=1, "100.0% (Package Over)", TEXT(MIN(G27*100, 99.9), "0.0") & "%") -> 66.3%

Sheet Rituparna_Banerjee
A1: CLIENT SESSION TRACKER: MISS RITUPARNA BANERJEE
A2: Start Date: 17/06/2025 | Package Details: Paid 5k for 7k pkg | Total Package Capacity: 300 Mins
A4: Session No. | B4: Session Date | C4: Duration (Mins/Value) | D4: Therapist / Details | E4: Cumulative Usage | F4: Remaining Balance | G4: % Package Consumed | H4: Prob. Package Over Date
A5: 1 | B5: 09/08/2025 | C5: 90 | D5: Soma / Tiya | E5: =C5 -> 90 | F5: =300-E5 -> 210 | G5: =E5/300 -> 30.0% | H5: =IF(G5>=1, "100.0% (Package Over)", TEXT(MIN(G5*100, 99.9), "0.0") & "%") -> 30.0%
A6: 2 | B6: 09/08/2025 | C6: 90 | D6: Pooja | E6: =E5+C6 -> 180 | F6: =300-E6 -> 120 | G6: =E6/300 -> 60.0% | H6: =IF(G6>=1, "100.0% (Package Over)", TEXT(MIN(G6*100, 99.9), "0.0") & "%") -> 60.0%

Sheet Murali_Panikar
A1: CLIENT SESSION TRACKER: MR. MURALI PANIKAR
A2: Start Date: 20/06/2025 | Package Details: 5k / 7.5k Package | Total Package Capacity: 360 Mins
A4: Session No. | B4: Session Date | C4: Duration (Mins/Value) | D4: Therapist / Details | E4: Cumulative Usage | F4: Remaining Balance | G4: % Package Consumed | H4: Prob. Package Over Date
A5: 1 | B5: 20/06/2025 | C5: 60 | D5: Ritika | E5: =C5 -> 60 | F5: =360-E5 -> 300 | G5: =E5/360 -> 16.7% | H5: =IF(G5>=1, "100.0% (Package Over)", TEXT(MIN(G5*100, 99.9), "0.0") & "%") -> 16.7%
A6: 2 | B6: 16/08/2025 | C6: 60 | D6: Tiya | E6: =E5+C6 -> 120 | F6: =360-E6 -> 240 | G6: =E6/360 -> 33.3% | H6: =IF(G6>=1, "100.0% (Package Over)", TEXT(MIN(G6*100, 99.9), "0.0") & "%") -> 33.3%
A7: 3 | B7: 26/10/2025 | C7: 140 | D7: Ritika | E7: =E6+C7 -> 260 | F7: =360-E7 -> 100 | G7: =E7/360 -> 72.2% | H7: =IF(G7>=1, "100.0% (Package Over)", TEXT(MIN(G7*100, 99.9), "0.0") & "%") -> 72.2%
A8: 4 | B8: 29/11/2025 | C8: 90 | D8: Sneha | E8: =E7+C8 -> 350 | F8: =360-E8 -> 10 | G8: =E8/360 -> 97.2% | H8: =IF(G8>=1, "100.0% (Package Over)", TEXT(MIN(G8*100, 99.9), "0.0") & "%") -> 97.2%
A9: 5 | B9: 14/12/2025 | C9: 60 | D9: HNS Foot / Sneha | E9: =E8+C9 -> 410 | F9: =360-E9 -> -50 | G9: =E9/360 -> 113.9% | H9: =IF(G9>=1, "100.0% (Package Over)", TEXT(MIN(G9*100, 99.9), "0.0") & "%") -> 100.0% (Package Over)

Sheet Supratim_Roy
A1: CLIENT SESSION TRACKER: MR. SUPRATIM ROY
A2: Start Date: 20/06/2025 | Package Details: Paid 5k for 7k Pkg | Total Package Capacity: 480 Mins
A4: Session No. | B4: Session Date | C4: Duration (Mins/Value) | D4: Therapist / Details | E4: Cumulative Usage | F4: Remaining Balance | G4: % Package Consumed | H4: Prob. Package Over Date
A5: 1 | B5: 20/06/2025 | C5: 60 | D5: Ritika | E5: =C5 -> 60 | F5: =480-E5 -> 420 | G5: =E5/480 -> 12.5% | H5: =IF(G5>=1, "100.0% (Package Over)", TEXT(MIN(G5*100, 99.9), "0.0") & "%") -> 12.5%
A6: 2 | B6: 22/06/2025 | C6: 60 | D6: Ritika | E6: =E5+C6 -> 120 | F6: =480-E6 -> 360 | G6: =E6/480 -> 25.0% | H6: =IF(G6>=1, "100.0% (Package Over)", TEXT(MIN(G6*100, 99.9), "0.0") & "%") -> 25.0%
A7: 3 | B7: 29/06/2025 | C7: 60 | D7: Ritika | E7: =E6+C7 -> 180 | F7: =480-E7 -> 300 | G7: =E7/480 -> 37.5% | H7: =IF(G7>=1, "100.0% (Package Over)", TEXT(MIN(G7*100, 99.9), "0.0") & "%") -> 37.5%
A8: 4 | B8: 10/07/2025 | C8: 90 | D8: Soma | E8: =E7+C8 -> 270 | F8: =480-E8 -> 210 | G8: =E8/480 -> 56.3% | H8: =IF(G8>=1, "100.0% (Package Over)", TEXT(MIN(G8*100, 99.9), "0.0") & "%") -> 56.3%
A9: 5 | B9: 10/07/2025 | C9: 90 | D9: Soma / Pedicure | E9: =E8+C9 -> 360 | F9: =480-E9 -> 120 | G9: =E9/480 -> 75.0% | H9: =IF(G9>=1, "100.0% (Package Over)", TEXT(MIN(G9*100, 99.9), "0.0") & "%") -> 75.0%
A10: 6 | B10: 28/07/2025 | C10: 120 | D10: Soma | E10: =E9+C10 -> 480 | F10: =480-E10 -> 0 | G10: =E10/480 -> 100.0% | H10: =IF(G10>=1, "100.0% (Package Over)", TEXT(MIN(G10*100, 99.9), "0.0") & "%") -> 100.0% (Package Over)
A11: 7 | B11: 28/07/2025 | C11: 120 | D11: Ritika | E11: =E10+C11 -> 600 | F11: =480-E11 -> -120 | G11: =E11/480 -> 125.0% | H11: =IF(G11>=1, "100.0% (Package Over)", TEXT(MIN(G11*100, 99.9), "0.0") & "%") -> 100.0% (Package Over)
A12: 8 | B12: 06/08/2025 | C12: 120 | D12: Ritika | E12: =E11+C12 -> 720 | F12: =480-E12 -> -240 | G12: =E12/480 -> 150.0% | H12: =IF(G12>=1, "100.0% (Package Over)", TEXT(MIN(G12*100, 99.9), "0.0") & "%") -> 100.0% (Package Over)

Sheet Anindita_Ghose
A1: CLIENT SESSION TRACKER: MISS ANINDITA GHOSE
A2: Start Date: 03/07/2025 | Package Details: Paid 5k for 7k (Not Started Yet) | Total Package Capacity: 300 Mins
A4: Session No. | B4: Session Date | C4: Duration (Mins/Value) | D4: Therapist / Details | E4: Cumulative Usage | F4: Remaining Balance | G4: % Package Consumed | H4: Prob. Package Over Date
A5: 1 | B5: 03/07/2025 | C5: 0 | D5: Not Started | E5: =C5 -> 0 | F5: =300-E5 -> 300 | G5: =E5/300 -> 0.0% | H5: =IF(G5>=1, "100.0% (Package Over)", TEXT(MIN(G5*100, 99.9), "0.0") & "%") -> 0.0%

Sheet Anand_Mehta
A1: CLIENT SESSION TRACKER: MR. ANAND MEHTA
A2: Start Date: 14/07/2025 | Package Details: Paid 6k for 10 Hours / 5k for 10 Hours | Total Package Capacity: 1200 Mins
A4: Session No. | B4: Session Date | C4: Duration (Mins/Value) | D4: Therapist / Details | E4: Cumulative Usage | F4: Remaining Balance | G4: % Package Consumed | H4: Prob. Package Over Date
A5: 1 | B5: 14/07/2025 | C5: 60 | D5: Soma | E5: =C5 -> 60 | F5: =1200-E5 -> 1,140 | G5: =E5/1200 -> 5.0% | H5: =IF(G5>=1, "100.0% (Package Over)", TEXT(MIN(G5*100, 99.9), "0.0") & "%") -> 5.0%
A6: 2 | B6: 16/07/2025 | C6: 60 | D6: Ritika | E6: =E5+C6 -> 120 | F6: =1200-E6 -> 1,080 | G6: =E6/1200 -> 10.0% | H6: =IF(G6>=1, "100.0% (Package Over)", TEXT(MIN(G6*100, 99.9), "0.0") & "%") -> 10.0%
A7: 3 | B7: 21/07/2025 | C7: 60 | D7: Ritika | E7: =E6+C7 -> 180 | F7: =1200-E7 -> 1,020 | G7: =E7/1200 -> 15.0% | H7: =IF(G7>=1, "100.0% (Package Over)", TEXT(MIN(G7*100, 99.9), "0.0") & "%") -> 15.0%
A8: 4 | B8: 28/07/2025 | C8: 60 | D8: Tiya | E8: =E7+C8 -> 240 | F8: =1200-E8 -> 960 | G8: =E8/1200 -> 20.0% | H8: =IF(G8>=1, "100.0% (Package Over)", TEXT(MIN(G8*100, 99.9), "0.0") & "%") -> 20.0%
A9: 5 | B9: 28/07/2025 | C9: 90 | D9: Soma | E9: =E8+C9 -> 330 | F9: =1200-E9 -> 870 | G9: =E9/1200 -> 27.5% | H9: =IF(G9>=1, "100.0% (Package Over)", TEXT(MIN(G9*100, 99.9), "0.0") & "%") -> 27.5%
A10: 6 | B10: 03/09/2025 | C10: 60 | D10: Soma | E10: =E9+C10 -> 390 | F10: =1200-E10 -> 810 | G10: =E10/1200 -> 32.5% | H10: =IF(G10>=1, "100.0% (Package Over)", TEXT(MIN(G10*100, 99.9), "0.0") & "%") -> 32.5%
A11: 7 | B11: 10/09/2025 | C11: 60 | D11: Soma | E11: =E10+C11 -> 450 | F11: =1200-E11 -> 750 | G11: =E11/1200 -> 37.5% | H11: =IF(G11>=1, "100.0% (Package Over)", TEXT(MIN(G11*100, 99.9), "0.0") & "%") -> 37.5%
A12: 8 | B12: 10/11/2025 | C12: 90 | D12: Ritika | E12: =E11+C12 -> 540 | F12: =1200-E12 -> 660 | G12: =E12/1200 -> 45.0% | H12: =IF(G12>=1, "100.0% (Package Over)", TEXT(MIN(G12*100, 99.9), "0.0") & "%") -> 45.0%
A13: 9 | B13: 22/11/2025 | C13: 60 | D13: Sneha | E13: =E12+C13 -> 600 | F13: =1200-E13 -> 600 | G13: =E13/1200 -> 50.0% | H13: =IF(G13>=1, "100.0% (Package Over)", TEXT(MIN(G13*100, 99.9), "0.0") & "%") -> 50.0%
A14: 10 | B14: 04/01/2026 | C14: 60 | D14: Riya | E14: =E13+C14 -> 660 | F14: =1200-E14 -> 540 | G14: =E14/1200 -> 55.0% | H14: =IF(G14>=1, "100.0% (Package Over)", TEXT(MIN(G14*100, 99.9), "0.0") & "%") -> 55.0%
A15: 11 | B15: 04/01/2026 | C15: 60 | D15: Daliya | E15: =E14+C15 -> 720 | F15: =1200-E15 -> 480 | G15: =E15/1200 -> 60.0% | H15: =IF(G15>=1, "100.0% (Package Over)", TEXT(MIN(G15*100, 99.9), "0.0") & "%") -> 60.0%
A16: 12 | B16: 14/01/2026 | C16: 60 | D16: Daliya | E16: =E15+C16 -> 780 | F16: =1200-E16 -> 420 | G16: =E16/1200 -> 65.0% | H16: =IF(G16>=1, "100.0% (Package Over)", TEXT(MIN(G16*100, 99.9), "0.0") & "%") -> 65.0%
A17: 13 | B17: 14/01/2026 | C17: 60 | D17: Soma | E17: =E16+C17 -> 840 | F17: =1200-E17 -> 360 | G17: =E17/1200 -> 70.0% | H17: =IF(G17>=1, "100.0% (Package Over)", TEXT(MIN(G17*100, 99.9), "0.0") & "%") -> 70.0%
... A23: 19 | B23: 18/03/2026 | C23: 60 | D23: Isha | E23: =E22+C23 -> 1,200 | F23: =1200-E23 -> 0 | G23: =E23/1200 -> 100.0% | H23: =IF(G23>=1, "100.0% (Package Over)", TEXT(MIN(G23*100, 99.9), "0.0") & "%") -> 100.0% (Package Over)

Sheet Subhabrata
A1: CLIENT SESSION TRACKER: MR. SUBHABRATA ROY
A2: Start Date: 18/07/2025 | Package Details: Paid 20k for 30 hrs (1800 Mins) | Total Package Capacity: 1800 Mins
A4: Session No. | B4: Session Date | C4: Duration (Mins/Value) | D4: Therapist / Details | E4: Cumulative Usage | F4: Remaining Balance | G4: % Package Consumed | H4: Prob. Package Over Date
A5: 1 | B5: 13/08/2026 | C5: 60 | D5: Foot - Sneha | E5: =C5 -> 60 | F5: =1800-E5 -> 1740 | G5: =E5/1800 -> 3.3% | H5: =IF(G5>=1, "100.0% (Package Over)", TEXT(MIN(G5*100, 99.9), "0.0") & "%") -> 3.3%
A6: 2 | B6: 13/08/2026 | C6: 90 | D6: FHNS - Daliya | E6: =E5+C6 -> 150 | F6: =1800-E6 -> 1650 | G6: =E6/1800 -> 8.3% | H6: =IF(G6>=1, "100.0% (Package Over)", TEXT(MIN(G6*100, 99.9), "0.0") & "%") -> 8.3%
A7: 3 | B7: 24/03/2026 | C7: 120 | D7: FHNS - Soma | E7: =E6+C7 -> 270 | F7: =1800-E7 -> 1530 | G7: =E7/1800 -> 15.0% | H7: =IF(G7>=1, "100.0% (Package Over)", TEXT(MIN(G7*100, 99.9), "0.0") & "%") -> 15.0%
A8: 4 | B8: 04/04/2026 | C8: 120 | D8: FHNS - Isha | E8: =E7+C8 -> 390 | F8: =1800-E8 -> 1410 | G8: =E8/1800 -> 21.7% | H8: =IF(G8>=1, "100.0% (Package Over)", TEXT(MIN(G8*100, 99.9), "0.0") & "%") -> 21.7%
A9: 5 | B9: 30/04/2026 | C9: 120 | D9: FHNS - Isha | E9: =E8+C9 -> 510 | F9: =1800-E9 -> 1290 | G9: =E9/1800 -> 28.3% | H9: =IF(G9>=1, "100.0% (Package Over)", TEXT(MIN(G9*100, 99.9), "0.0") & "%") -> 28.3%
A10: 6 | B10: 15/05/2026 | C10: 90 | D10: FHNS - Riya | E10: =E9+C10 -> 600 | F10: =1800-E10 -> 1200 | G10: =E10/1800 -> 33.3% | H10: =IF(G10>=1, "100.0% (Package Over)", TEXT(MIN(G10*100, 99.9), "0.0") & "%") -> 33.3%
A11: 7 | B11: 10/06/2026 | C11: 90 | D11: FHNS - Bipasha | E11: =E10+C11 -> 690 | F11: =1800-E11 -> 1110 | G11: =E11/1800 -> 38.3% | H11: =IF(G11>=1, "100.0% (Package Over)", TEXT(MIN(G11*100, 99.9), "0.0") & "%") -> 38.3%
A12: 8 | B12: 22/06/2026 | C12: 90 | D12: FHNS - Bipasha | E12: =E11+C12 -> 780 | F12: =1800-E12 -> 1020 | G12: =E12/1800 -> 43.3% | H12: =IF(G12>=1, "100.0% (Package Over)", TEXT(MIN(G12*100, 99.9), "0.0") & "%") -> 43.3%
A13: 9 | B13: 30/06/2026 | C13: 120 | D13: FHNS - Bipasha | E13: =E12+C13 -> 900 | F13: =1800-E13 -> 900 | G13: =E13/1800 -> 50.0% | H13: =IF(G13>=1, "100.0% (Package Over)", TEXT(MIN(G13*100, 99.9), "0.0") & "%") -> 50.0%
A14: 10 | B14: 09/07/2026 | C14: 90 | D14: FHNS - Puja | E14: =E13+C14 -> 990 | F14: =1800-E14 -> 810 | G14: =E14/1800 -> 55.0% | H14: =IF(G14>=1, "100.0% (Package Over)", TEXT(MIN(G14*100, 99.9), "0.0") & "%") -> 55.0%
A15: 11 | B15: 21/07/2026 | C15: 90 | D15: FHNS - Puja | E15: =E14+C15 -> 1080 | F15: =1800-E15 -> 720 | G15: =E15/1800 -> 60.0% | H15: =IF(G15>=1, "100.0% (Package Over)", TEXT(MIN(G15*100, 99.9), "0.0") & "%") -> 60.0%
A16: 12 | B16: 21/07/2026 | C16: 120 | D16: FHNS - Ankit | E16: =E15+C16 -> 1200 | F16: =1800-E16 -> 600 | G16: =E16/1800 -> 66.7% | H16: =IF(G16>=1, "100.0% (Package Over)", TEXT(MIN(G16*100, 99.9), "0.0") & "%") -> 66.7%
A17: 13 | B17: 21/08/2026 | C17: 90 | D17: FHNS - Pinky | E17: =E16+C17 -> 1290 | F17: =1800-E17 -> 510 | G17: =E17/1800 -> 71.7% | H17: =IF(G17>=1, "100.0% (Package Over)", TEXT(MIN(G17*100, 99.9), "0.0") & "%") -> 71.7%

Sheet Sushanta
A1: CLIENT SESSION TRACKER: MR. SUSHANTA BHATTACHARYA
A2: Start Date: 20/07/2025 | Package Details: 50k for 80 hr + 5k Paid for 20 hr (Not Started Yet) | Total Package Capacity: 6000 Mins
A4: Session No. | B4: Session Date | C4: Duration (Mins/Value) | D4: Therapist / Details | E4: Cumulative Usage | F4: Remaining Balance | G4: % Package Consumed | H4: Prob. Package Over Date
A5: 1 | B5: 02/11/2025 | C5: 0 | D5: Not Started Yet (5k Paid for 20 hr) | E5: =C5 -> 0 | F5: =6000-E5 -> 6000 | G5: =E5/6000 -> 0.0% | H5: =IF(G5>=1, "100.0% (Package Over)", TEXT(MIN(G5*100, 99.9), "0.0") & "%") -> 0.0%

Sheet Anand_Poddar
A1: CLIENT SESSION TRACKER: MR. ANAND PODDAR
A2: Start Date: 22/07/2025 | Package Details: Paid 5k for 7 Hours | Total Package Capacity: 420 Mins
A4: Session No. | B4: Session Date | C4: Duration (Mins/Value) | D4: Therapist / Details | E4: Cumulative Usage | F4: Remaining Balance | G4: % Package Consumed | H4: Prob. Package Over Date
A5: 1 | B5: 22/07/2025 | C5: 60 | D5: Ritvika | E5: =C5 -> 60 | F5: =420-E5 -> 360 | G5: =E5/420 -> 14.3% | H5: =IF(G5>=1, "100.0% (Package Over)", TEXT(MIN(G5*100, 99.9), "0.0") & "%") -> 14.3%
A6: 2 | B6: 14/08/2025 | C6: 60 | D6: Puja | E6: =E5+C6 -> 120 | F6: =420-E6 -> 300 | G6: =E6/420 -> 28.6% | H6: =IF(G6>=1, "100.0% (Package Over)", TEXT(MIN(G6*100, 99.9), "0.0") & "%") -> 28.6%
A7: 3 | B7: 17/08/2025 | C7: 30 | D7: Puja | E7: =E6+C7 -> 150 | F7: =420-E7 -> 270 | G7: =E7/420 -> 35.7% | H7: =IF(G7>=1, "100.0% (Package Over)", TEXT(MIN(G7*100, 99.9), "0.0") & "%") -> 35.7%
A8: 4 | B8: 23/08/2025 | C8: 60 | D8: Puja | E8: =E7+C8 -> 210 | F8: =420-E8 -> 210 | G8: =E8/420 -> 50.0% | H8: =IF(G8>=1, "100.0% (Package Over)", TEXT(MIN(G8*100, 99.9), "0.0") & "%") -> 50.0%
A9: 5 | B9: 12/09/2025 | C9: 75 | D9: Soma | E9: =E8+C9 -> 285 | F9: =420-E9 -> 135 | G9: =E9/420 -> 67.9% | H9: =IF(G9>=1, "100.0% (Package Over)", TEXT(MIN(G9*100, 99.9), "0.0") & "%") -> 67.9%
A10: 6 | B10: 10/10/2025 | C10: 60 | D10: Soma | E10: =E9+C10 -> 345 | F10: =420-E10 -> 75 | G10: =E10/420 -> 82.1% | H10: =IF(G10>=1, "100.0% (Package Over)", TEXT(MIN(G10*100, 99.9), "0.0") & "%") -> 82.1%
A11: 7 | B11: 12/03/2026 | C11: 60 | D11: Isha | E11: =E10+C11 -> 405 | F11: =420-E11 -> 15 | G11: =E11/420 -> 96.4% | H11: =IF(G11>=1, "100.0% (Package Over)", TEXT(MIN(G11*100, 99.9), "0.0") & "%") -> 96.4%
A12: 8 | B12: 26/03/2026 | C12: 15 | D12: Soma | E12: =E11+C12 -> 420 | F12: =420-E12 -> 0 | G12: =E12/420 -> 100.0% | H12: =IF(G12>=1, "100.0% (Package Over)", TEXT(MIN(G12*100, 99.9), "0.0") & "%") -> 100.0% (Package Over)

Sheet Debabrata_Dey
A1: CLIENT SESSION TRACKER: MR. DEBABRATA DEY
A2: Start Date: 23/07/2025 | Package Details: Paid 5k for 7k Package (Soma) | Total Package Capacity: 7000
A4: Session No. | B4: Session Date | C4: Duration (Mins/Value) | D4: Therapist / Details | E4: Cumulative Usage | F4: Remaining Balance | G4: % Package Consumed | H4: Prob. Package Over Date
A5: 1 | B5: 23/07/2025 | C5: 2508 | D5: Facial - Soma | E5: =C5 -> 2,508 | F5: =7000-E5 -> 4,492 | G5: =E5/7000 -> 35.8% | H5: =IF(G5>=1, "100.0% (Package Over)", TEXT(MIN(G5*100, 99.9), "0.0") & "%") -> 35.8%
A6: 2 | B6: 12/08/2025 | C6: 2950 | D6: Facial - Soma | E6: =E5+C6 -> 5,458 | F6: =7000-E6 -> 1,542 | G6: =E6/7000 -> 78.0% | H6: =IF(G6>=1, "100.0% (Package Over)", TEXT(MIN(G6*100, 99.9), "0.0") & "%") -> 78.0%
A7: 3 | B7: 09/09/2025 | C7: 950 | D7: Facial - Soma | E7: =E6+C7 -> 6,408 | F7: =7000-E7 -> 592 | G7: =E7/7000 -> 91.5% | H7: =IF(G7>=1, "100.0% (Package Over)", TEXT(MIN(G7*100, 99.9), "0.0") & "%") -> 91.5%
A8: 4 | B8: 25/11/2025 | C8: 592 | D8: Facial - Sneha (Paid = 358 left/over) | E8: =E7+C8 -> 7,000 | F8: =7000-E8 -> 0 | G8: =E8/7000 -> 100.0% | H8: =IF(G8>=1, "100.0% (Package Over)", TEXT(MIN(G8*100, 99.9), "0.0") & "%") -> 100.0% (Package Over)

Sheet Madhumita_Chatterjee
A1: CLIENT SESSION TRACKER: MADHUMITA CHATTERJEE / DEY
A2: Start Date: 07/08/2025 | Package Details: Paid 5k for 7 Hours + Paid 5k for 7k Value (10/11/25) + Paid 5k for 7k Value (28/12/25) | Phone: 8240366754 | Total Capacity: 14420 Value/Mins
A4: Session No. | B4: Session Date | C4: Duration (Mins/Value) | D4: Therapist / Details | E4: Cumulative Usage | F4: Remaining Balance | G4: % Package Consumed | H4: Prob. Package Over Date
A5: 1 | B5: 07/08/2025 | C5: 60 | D5: Soma | E5: =C5 -> 60 | F5: =14420-E5 -> 14360 | G5: =E5/14420 -> 0.4% | H5: =IF(G5>=1, "100.0% (Package Over)", TEXT(MIN(G5*100, 99.9), "0.0") & "%") -> 0.4%
A6: 2 | B6: 11/08/2025 | C6: 60 | D6: Soma | E6: =E5+C6 -> 120 | F6: =14420-E6 -> 14300 | G6: =E6/14420 -> 0.8% | H6: =IF(G6>=1, "100.0% (Package Over)", TEXT(MIN(G6*100, 99.9), "0.0") & "%") -> 0.8%
A7: 3 | B7: 19/08/2025 | C7: 60 | D7: Soma | E7: =E6+C7 -> 180 | F7: =14420-E7 -> 14240 | G7: =E7/14420 -> 1.2% | H7: =IF(G7>=1, "100.0% (Package Over)", TEXT(MIN(G7*100, 99.9), "0.0") & "%") -> 1.2%
A8: 4 | B8: 28/08/2025 | C8: 60 | D8: Anju | E8: =E7+C8 -> 240 | F8: =14420-E8 -> 14180 | G8: =E8/14420 -> 1.7% | H8: =IF(G8>=1, "100.0% (Package Over)", TEXT(MIN(G8*100, 99.9), "0.0") & "%") -> 1.7%
A9: 5 | B9: 21/09/2025 | C9: 60 | D9: Soma | E9: =E8+C9 -> 300 | F9: =14420-E9 -> 14120 | G9: =E9/14420 -> 2.1% | H9: =IF(G9>=1, "100.0% (Package Over)", TEXT(MIN(G9*100, 99.9), "0.0") & "%") -> 2.1%
A10: 6 | B10: 16/09/2025 | C10: 60 | D10: Soma | E10: =E9+C10 -> 360 | F10: =14420-E10 -> 14060 | G10: =E10/14420 -> 2.5% | H10: =IF(G10>=1, "100.0% (Package Over)", TEXT(MIN(G10*100, 99.9), "0.0") & "%") -> 2.5%
A11: 7 | B11: 28/09/2025 | C11: 60 | D11: Soma | E11: =E10+C11 -> 420 | F11: =14420-E11 -> 14000 | G11: =E11/14420 -> 2.9% | H11: =IF(G11>=1, "100.0% (Package Over)", TEXT(MIN(G11*100, 99.9), "0.0") & "%") -> 2.9%
A12: 8 | B12: 10/11/2025 | C12: 650 | D12: Classic Pedicure (Soma) - Madhumita Dey | E12: =E11+C12 -> 1070 | F12: =14420-E12 -> 13350 | G12: =E12/14420 -> 7.4% | H12: =IF(G12>=1, "100.0% (Package Over)", TEXT(MIN(G12*100, 99.9), "0.0") & "%") -> 7.4%
A13: 9 | B13: 10/11/2025 | C13: 950 | D13: Aroma Therapy (Soma) - Madhumita Dey | E13: =E12+C13 -> 2020 | F13: =14420-E13 -> 12400 | G13: =E13/14420 -> 14.0% | H13: =IF(G13>=1, "100.0% (Package Over)", TEXT(MIN(G13*100, 99.9), "0.0") & "%") -> 14.0%
A14: 10 | B14: 16/11/2025 | C14: 950 | D14: Foot Therapy (Ritika) - Madhumita Dey | E14: =E13+C14 -> 2970 | F14: =14420-E14 -> 11450 | G14: =E14/14420 -> 20.6% | H14: =IF(G14>=1, "100.0% (Package Over)", TEXT(MIN(G14*100, 99.9), "0.0") & "%") -> 20.6%
A15: 11 | B15: 16/11/2025 | C15: 950 | D15: Foot Therapy (Sneha) - Madhumita Dey | E15: =E14+C15 -> 3920 | F15: =14420-E15 -> 10500 | G15: =E15/14420 -> 27.2% | H15: =IF(G15>=1, "100.0% (Package Over)", TEXT(MIN(G15*100, 99.9), "0.0") & "%") -> 27.2%
A16: 12 | B16: 28/12/2025 | C16: 950 | D16: Foot Therapy (Daliya) - Madhumita Dey | E16: =E15+C16 -> 4870 | F16: =14420-E16 -> 9550 | G16: =E16/14420 -> 33.8% | H16: =IF(G16>=1, "100.0% (Package Over)", TEXT(MIN(G16*100, 99.9), "0.0") & "%") -> 33.8%
A17: 13 | B17: 28/12/2025 | C17: 850 | D17: Deluxe Pedicure (Sneha) - Madhumita Dey | E17: =E16+C17 -> 5720 | F17: =14420-E17 -> 8700 | G17: =E17/14420 -> 39.7% | H17: =IF(G17>=1, "100.0% (Package Over)", TEXT(MIN(G17*100, 99.9), "0.0") & "%") -> 39.7%
... A21: 17 | B21: 05/01/2026 | C21: 950 | D21: Foot Therapy FHNS (Pooja) - Madhumita Dey | E21: =E20+C21 -> 9420 | F21: =14420-E21 -> 5000 | G21: =E21/14420 -> 65.3% | H21: =IF(G21>=1, "100.0% (Package Over)", TEXT(MIN(G21*100, 99.9), "0.0") & "%") -> 65.3%

Sheet Randhir_Paul
A1: CLIENT SESSION TRACKER: MR. RANDHIR PAUL
A2: Start Date: 13/08/2025 | Package Details: Paid 5k for 10 hrs x2 + Paid 5k for 10 Sessions (30/10/25) + Paid 5k for 10 Sessions (21/12/25) | Total Package Capacity: 2400 Mins
A4: Session No. | B4: Session Date | C4: Duration (Mins/Value) | D4: Therapist / Details | E4: Cumulative Usage | F4: Remaining Balance | G4: % Package Consumed | H4: Prob. Package Over Date
A5: 1 | B5: 13/08/2025 | C5: 60 | D5: Puja | E5: =C5 -> 60 | F5: =2400-E5 -> 2340 | G5: =E5/2400 -> 2.5% | H5: =IF(G5>=1, "100.0% (Package Over)", TEXT(MIN(G5*100, 99.9), "0.0") & "%") -> 2.5%
A6: 2 | B6: 19/08/2025 | C6: 90 | D6: Puja | E6: =E5+C6 -> 150 | F6: =2400-E6 -> 2250 | G6: =E6/2400 -> 6.3% | H6: =IF(G6>=1, "100.0% (Package Over)", TEXT(MIN(G6*100, 99.9), "0.0") & "%") -> 6.3%
A7: 3 | B7: 26/08/2025 | C7: 90 | D7: Barsha | E7: =E6+C7 -> 240 | F7: =2400-E7 -> 2160 | G7: =E7/2400 -> 10.0% | H7: =IF(G7>=1, "100.0% (Package Over)", TEXT(MIN(G7*100, 99.9), "0.0") & "%") -> 10.0%
A8: 4 | B8: 02/09/2025 | C8: 90 | D8: Soma | E8: =E7+C8 -> 330 | F8: =2400-E8 -> 2070 | G8: =E8/2400 -> 13.8% | H8: =IF(G8>=1, "100.0% (Package Over)", TEXT(MIN(G8*100, 99.9), "0.0") & "%") -> 13.8%
A9: 5 | B9: 09/09/2025 | C9: 90 | D9: Suparna | E9: =E8+C9 -> 420 | F9: =2400-E9 -> 1980 | G9: =E9/2400 -> 17.5% | H9: =IF(G9>=1, "100.0% (Package Over)", TEXT(MIN(G9*100, 99.9), "0.0") & "%") -> 17.5%
A10: 6 | B10: 11/09/2025 | C10: 60 | D10: Suparna | E10: =E9+C10 -> 480 | F10: =2400-E10 -> 1920 | G10: =E10/2400 -> 20.0% | H10: =IF(G10>=1, "100.0% (Package Over)", TEXT(MIN(G10*100, 99.9), "0.0") & "%") -> 20.0%
A11: 7 | B11: 15/09/2025 | C11: 90 | D11: Suparna | E11: =E10+C11 -> 570 | F11: =2400-E11 -> 1830 | G11: =E11/2400 -> 23.8% | H11: =IF(G11>=1, "100.0% (Package Over)", TEXT(MIN(G11*100, 99.9), "0.0") & "%") -> 23.8%
A12: 8 | B12: 18/09/2025 | C12: 30 | D12: Suparna (Over) | E12: =E11+C12 -> 600 | F12: =2400-E12 -> 1800 | G12: =E12/2400 -> 25.0% | H12: =IF(G12>=1, "100.0% (Package Over)", TEXT(MIN(G12*100, 99.9), "0.0") & "%") -> 25.0%
A13: 9 | B13: 18/09/2025 | C13: 60 | D13: Suparna (Pkg 2 Renewal) | E13: =E12+C13 -> 660 | F13: =2400-E13 -> 1740 | G13: =E13/2400 -> 27.5% | H13: =IF(G13>=1, "100.0% (Package Over)", TEXT(MIN(G13*100, 99.9), "0.0") & "%") -> 27.5%
A14: 10 | B14: 26/09/2025 | C14: 60 | D14: Suparna | E14: =E13+C14 -> 720 | F14: =2400-E14 -> 1680 | G14: =E14/2400 -> 30.0% | H14: =IF(G14>=1, "100.0% (Package Over)", TEXT(MIN(G14*100, 99.9), "0.0") & "%") -> 30.0%
A15: 11 | B15: 07/10/2025 | C15: 60 | D15: Soma | E15: =E14+C15 -> 780 | F15: =2400-E15 -> 1620 | G15: =E15/2400 -> 32.5% | H15: =IF(G15>=1, "100.0% (Package Over)", TEXT(MIN(G15*100, 99.9), "0.0") & "%") -> 32.5%
A16: 12 | B16: 24/10/2025 | C16: 60 | D16: Sneha | E16: =E15+C16 -> 840 | F16: =2400-E16 -> 1560 | G16: =E16/2400 -> 35.0% | H16: =IF(G16>=1, "100.0% (Package Over)", TEXT(MIN(G16*100, 99.9), "0.0") & "%") -> 35.0%
A17: 13 | B17: 30/10/2025 | C17: 90 | D17: Sneha | E17: =E16+C17 -> 930 | F17: =2400-E17 -> 1470 | G17: =E17/2400 -> 38.8% | H17: =IF(G17>=1, "100.0% (Package Over)", TEXT(MIN(G17*100, 99.9), "0.0") & "%") -> 38.8%
... A32: 28 | B32: 11/03/2026 | C32: 90 | D32: Isha - FHNS (Randhir Pal) | E32: =E31+C32 -> 2100 | F32: =2400-E32 -> 300 | G32: =E32/2400 -> 87.5% | H32: =IF(G32>=1, "100.0% (Package Over)", TEXT(MIN(G32*100, 99.9), "0.0") & "%") -> 87.5%

Sheet Manish_Jaiswal
A1: CLIENT SESSION TRACKER: MANISH JAISWAL / PANKAJ JAISNEEL (MERGED)
A2: Start Date: 14/08/2025 | Package Details: Paid 5k for 8k Cash + Paid 5k for 10 hrs (31/10/25) + Paid 5k for 10 hrs (14/01/26) | Total Package Capacity: 9200 Value/Mins
A4: Session No. | B4: Session Date | C4: Duration (Mins/Value) | D4: Therapist / Details | E4: Cumulative Usage | F4: Remaining Balance | G4: % Package Consumed | H4: Prob. Package Over Date
A5: 1 | B5: 14/08/2025 | C5: 850 | D5: Pedicure | E5: =C5 -> 850 | F5: =9200-E5 -> 8350 | G5: =E5/9200 -> 9.2% | H5: =IF(G5>=1, "100.0% (Package Over)", TEXT(MIN(G5*100, 99.9), "0.0") & "%") -> 9.2%
A6: 2 | B6: 15/08/2025 | C6: 2600 | D6: Foot Massage 60 min (950 - Puja) + Detox Facial (1650 - Soma) | E6: =E5+C6 -> 3450 | F6: =9200-E6 -> 5750 | G6: =E6/9200 -> 37.5% | H6: =IF(G6>=1, "100.0% (Package Over)", TEXT(MIN(G6*100, 99.9), "0.0") & "%") -> 37.5%
A7: 3 | B7: 04/09/2025 | C7: 2500 | D7: Pedicure (850 - Suparna) + Detox Facial (1650 - Soma) | E7: =E6+C7 -> 5950 | F7: =9200-E7 -> 3250 | G7: =E7/9200 -> 64.7% | H7: =IF(G7>=1, "100.0% (Package Over)", TEXT(MIN(G7*100, 99.9), "0.0") & "%") -> 64.7%
A8: 4 | B8: 01/12/2025 | C8: 1250 | D8: Signature Pedicure (1250 - Soma) | E8: =E7+C8 -> 7200 | F8: =9200-E8 -> 2000 | G8: =E8/9200 -> 78.3% | H8: =IF(G8>=1, "100.0% (Package Over)", TEXT(MIN(G8*100, 99.9), "0.0") & "%") -> 78.3%
A9: 5 | B9: 11/12/2025 | C9: 1250 | D9: Signature Pedicure (Sneha - 800 balance + 450 paid = 1250) [OVER] | E9: =E8+C9 -> 8450 | F9: =9200-E9 -> 750 | G9: =E9/9200 -> 91.8% | H9: =IF(G9>=1, "100.0% (Package Over)", TEXT(MIN(G9*100, 99.9), "0.0") & "%") -> 91.8%
A10: 6 | B10: 03/11/2025 | C10: 60 | D10: Soma (Pankaj Jaisneel) | E10: =E9+C10 -> 8510 | F10: =9200-E10 -> 690 | G10: =E10/9200 -> 92.5% | H10: =IF(G10>=1, "100.0% (Package Over)", TEXT(MIN(G10*100, 99.9), "0.0") & "%") -> 92.5%
A11: 7 | B11: 15/11/2025 | C11: 60 | D11: Ritika (Pankaj Jaisneel) | E11: =E10+C11 -> 8570 | F11: =9200-E11 -> 630 | G11: =E11/9200 -> 93.2% | H11: =IF(G11>=1, "100.0% (Package Over)", TEXT(MIN(G11*100, 99.9), "0.0") & "%") -> 93.2%
A12: 8 | B12: 18/11/2025 | C12: 60 | D12: Sneha (Pankaj Jaisneel) | E12: =E11+C12 -> 8630 | F12: =9200-E12 -> 570 | G12: =E12/9200 -> 93.8% | H12: =IF(G12>=1, "100.0% (Package Over)", TEXT(MIN(G12*100, 99.9), "0.0") & "%") -> 93.8%
A13: 9 | B13: 25/11/2025 | C13: 60 | D13: Sneha (Pankaj Jaisneel) | E13: =E12+C13 -> 8690 | F13: =9200-E13 -> 510 | G13: =E13/9200 -> 94.5% | H13: =IF(G13>=1, "100.0% (Package Over)", TEXT(MIN(G13*100, 99.9), "0.0") & "%") -> 94.5%
A14: 10 | B14: 04/12/2025 | C14: 60 | D14: Soma (Pankaj Jaisneel) | E14: =E13+C14 -> 8750 | F14: =9200-E14 -> 450 | G14: =E14/9200 -> 95.1% | H14: =IF(G14>=1, "100.0% (Package Over)", TEXT(MIN(G14*100, 99.9), "0.0") & "%") -> 95.1%
A15: 11 | B15: 21/01/2026 | C15: 60 | D15: Pratima (Pankaj Jaisneel) | E15: =E14+C15 -> 8810 | F15: =9200-E15 -> 390 | G15: =E15/9200 -> 95.8% | H15: =IF(G15>=1, "100.0% (Package Over)", TEXT(MIN(G15*100, 99.9), "0.0") & "%") -> 95.8%
A16: 12 | B16: 14/01/2026 | C16: 60 | D16: Daliya (Pankaj Jaisneel) | E16: =E15+C16 -> 8870 | F16: =9200-E16 -> 330 | G16: =E16/9200 -> 96.4% | H16: =IF(G16>=1, "100.0% (Package Over)", TEXT(MIN(G16*100, 99.9), "0.0") & "%") -> 96.4%
A17: 13 | B17: 19/01/2026 | C17: 60 | D17: Daliya (Pankaj Jaisneel) | E17: =E16+C17 -> 8930 | F17: =9200-E17 -> 270 | G17: =E17/9200 -> 97.1% | H17: =IF(G17>=1, "100.0% (Package Over)", TEXT(MIN(G17*100, 99.9), "0.0") & "%") -> 97.1%
... A25: 21 | B25: 19/08/2026 | C25: 60 | D25: Ankit - FHNS (Pankaj Jaisneel) | E25: =E24+C25 -> 9410 | F25: =9200-E25 -> -210 | G25: =E25/9200 -> 102.3% | H25: =IF(G25>=1, "100.0% (Package Over)", TEXT(MIN(G25*100, 99.9), "0.0") & "%") -> 100.0% (Package Over)

Sheet RC_Yadav
A1: CLIENT SESSION TRACKER: DR. R.C. YADAV (MERGED)
A2: Start Date: 15/08/2025 | Package Details: Paid 5k for 10 hrs + Paid 5k for Self + Paid 5k for 10 hrs (24/10/25) + Aroma Facial Pkg 5k for 10 hrs (16/12/25) | Total Package Capacity: 2400 Mins
A4: Session No. | B4: Session Date | C4: Duration (Mins/Value) | D4: Therapist / Details | E4: Cumulative Usage | F4: Remaining Balance | G4: % Package Consumed | H4: Prob. Package Over Date
A5: 1 | B5: 15/08/2025 | C5: 60 | D5: Soma | E5: =C5 -> 60 | F5: =2400-E5 -> 2340 | G5: =E5/2400 -> 2.5% | H5: =IF(G5>=1, "100.0% (Package Over)", TEXT(MIN(G5*100, 99.9), "0.0") & "%") -> 2.5%
A6: 2 | B6: 17/08/2025 | C6: 60 | D6: Soma | E6: =E5+C6 -> 120 | F6: =2400-E6 -> 2280 | G6: =E6/2400 -> 5.0% | H6: =IF(G6>=1, "100.0% (Package Over)", TEXT(MIN(G6*100, 99.9), "0.0") & "%") -> 5.0%
A7: 3 | B7: 19/08/2025 | C7: 60 | D7: Soma | E7: =E6+C7 -> 180 | F7: =2400-E7 -> 2220 | G7: =E7/2400 -> 7.5% | H7: =IF(G7>=1, "100.0% (Package Over)", TEXT(MIN(G7*100, 99.9), "0.0") & "%") -> 7.5%
A8: 4 | B8: 24/09/2025 | C8: 60 | D8: Suparna | E8: =E7+C8 -> 240 | F8: =2400-E8 -> 2160 | G8: =E8/2400 -> 10.0% | H8: =IF(G8>=1, "100.0% (Package Over)", TEXT(MIN(G8*100, 99.9), "0.0") & "%") -> 10.0%
A9: 5 | B9: 10/10/2025 | C9: 60 | D9: Soma | E9: =E8+C9 -> 300 | F9: =2400-E9 -> 2100 | G9: =E9/2400 -> 12.5% | H9: =IF(G9>=1, "100.0% (Package Over)", TEXT(MIN(G9*100, 99.9), "0.0") & "%") -> 12.5%
A10: 6 | B10: 14/10/2025 | C10: 60 | D10: Ritika | E10: =E9+C10 -> 360 | F10: =2400-E10 -> 2040 | G10: =E10/2400 -> 15.0% | H10: =IF(G10>=1, "100.0% (Package Over)", TEXT(MIN(G10*100, 99.9), "0.0") & "%") -> 15.0%
A11: 7 | B11: 16/10/2025 | C11: 60 | D11: Soma | E11: =E10+C11 -> 420 | F11: =2400-E11 -> 1980 | G11: =E11/2400 -> 17.5% | H11: =IF(G11>=1, "100.0% (Package Over)", TEXT(MIN(G11*100, 99.9), "0.0") & "%") -> 17.5%
A12: 8 | B12: 18/10/2025 | C12: 60 | D12: Ritika | E12: =E11+C12 -> 480 | F12: =2400-E12 -> 1920 | G12: =E12/2400 -> 20.0% | H12: =IF(G12>=1, "100.0% (Package Over)", TEXT(MIN(G12*100, 99.9), "0.0") & "%") -> 20.0%
A13: 9 | B13: 18/10/2025 | C13: 60 | D13: Soma | E13: =E12+C13 -> 540 | F13: =2400-E13 -> 1860 | G13: =E13/2400 -> 22.5% | H13: =IF(G13>=1, "100.0% (Package Over)", TEXT(MIN(G13*100, 99.9), "0.0") & "%") -> 22.5%
A14: 10 | B14: 22/10/2025 | C14: 60 | D14: Soma | E14: =E13+C14 -> 600 | F14: =2400-E14 -> 1800 | G14: =E14/2400 -> 25.0% | H14: =IF(G14>=1, "100.0% (Package Over)", TEXT(MIN(G14*100, 99.9), "0.0") & "%") -> 25.0%
A15: 11 | B15: 24/10/2025 | C15: 60 | D15: Ritika | E15: =E14+C15 -> 660 | F15: =2400-E15 -> 1740 | G15: =E15/2400 -> 27.5% | H15: =IF(G15>=1, "100.0% (Package Over)", TEXT(MIN(G15*100, 99.9), "0.0") & "%") -> 27.5%
A16: 12 | B16: 27/10/2025 | C16: 60 | D16: Soma | E16: =E15+C16 -> 720 | F16: =2400-E16 -> 1680 | G16: =E16/2400 -> 30.0% | H16: =IF(G16>=1, "100.0% (Package Over)", TEXT(MIN(G16*100, 99.9), "0.0") & "%") -> 30.0%
A17: 13 | B17: 29/10/2025 | C17: 60 | D17: Soma | E17: =E16+C17 -> 780 | F17: =2400-E17 -> 1620 | G17: =E17/2400 -> 32.5% | H17: =IF(G17>=1, "100.0% (Package Over)", TEXT(MIN(G17*100, 99.9), "0.0") & "%") -> 32.5%
... A45: 41 | B45: 12/03/2026 | C45: 60 | D45: Foot HNS - Isha (R.C. Yadav) | E45: =E44+C45 -> 2520 | F45: =2400-E45 -> -120 | G45: =E45/2400 -> 105.0% | H45: =IF(G45>=1, "100.0% (Package Over)", TEXT(MIN(G45*100, 99.9), "0.0") & "%") -> 100.0% (Package Over)

Sheet Indrajit_Basak
A1: CLIENT SESSION TRACKER: MR. INDRAJIT BASAK (MERGED)
A2: Start Date: 18/08/2025 | Package Details: Paid 5k for 8 hrs + New Package Paid 5k for 8 hrs | Total Package Capacity: 960 Mins
A4: Session No. | B4: Session Date | C4: Duration (Mins/Value) | D4: Therapist / Details | E4: Cumulative Usage | F4: Remaining Balance | G4: % Package Consumed | H4: Prob. Package Over Date
A5: 1 | B5: 18/08/2025 | C5: 60 | D5: Soma | E5: =C5 -> 60 | F5: =960-E5 -> 900 | G5: =E5/960 -> 6.3% | H5: =IF(G5>=1, "100.0% (Package Over)", TEXT(MIN(G5*100, 99.9), "0.0") & "%") -> 6.3%
A6: 2 | B6: 27/08/2025 | C6: 60 | D6: Rajlakshmi | E6: =E5+C6 -> 120 | F6: =960-E6 -> 840 | G6: =E6/960 -> 12.5% | H6: =IF(G6>=1, "100.0% (Package Over)", TEXT(MIN(G6*100, 99.9), "0.0") & "%") -> 12.5%
A7: 3 | B7: 05/09/2025 | C7: 60 | D7: Soma | E7: =E6+C7 -> 180 | F7: =960-E7 -> 780 | G7: =E7/960 -> 18.8% | H7: =IF(G7>=1, "100.0% (Package Over)", TEXT(MIN(G7*100, 99.9), "0.0") & "%") -> 18.8%
A8: 4 | B8: 08/09/2025 | C8: 60 | D8: Soma | E8: =E7+C8 -> 240 | F8: =960-E8 -> 720 | G8: =E8/960 -> 25.0% | H8: =IF(G8>=1, "100.0% (Package Over)", TEXT(MIN(G8*100, 99.9), "0.0") & "%") -> 25.0%
A9: 5 | B9: 03/10/2025 | C9: 60 | D9: Soma | E9: =E8+C9 -> 300 | F9: =960-E9 -> 660 | G9: =E9/960 -> 31.3% | H9: =IF(G9>=1, "100.0% (Package Over)", TEXT(MIN(G9*100, 99.9), "0.0") & "%") -> 31.3%
A10: 6 | B10: 25/12/2025 | C10: 60 | D10: Daliya | E10: =E9+C10 -> 360 | F10: =960-E10 -> 600 | G10: =E10/960 -> 37.5% | H10: =IF(G10>=1, "100.0% (Package Over)", TEXT(MIN(G10*100, 99.9), "0.0") & "%") -> 37.5%
A11: 7 | B11: 14/01/2026 | C11: 60 | D11: Riya | E11: =E10+C11 -> 420 | F11: =960-E11 -> 540 | G11: =E11/960 -> 43.8% | H11: =IF(G11>=1, "100.0% (Package Over)", TEXT(MIN(G11*100, 99.9), "0.0") & "%") -> 43.8%
A12: 8 | B12: 15/01/2026 | C12: 60 | D12: Daliya (Foot) | E12: =E11+C12 -> 480 | F12: =960-E12 -> 480 | G12: =E12/960 -> 50.0% | H12: =IF(G12>=1, "100.0% (Package Over)", TEXT(MIN(G12*100, 99.9), "0.0") & "%") -> 50.0%
A13: 9 | B13: 15/01/2026 | C13: 60 | D13: Soma (HNS) | E13: =E12+C13 -> 540 | F13: =960-E13 -> 420 | G13: =E13/960 -> 56.3% | H13: =IF(G13>=1, "100.0% (Package Over)", TEXT(MIN(G13*100, 99.9), "0.0") & "%") -> 56.3%
A14: 10 | B14: 06/02/2026 | C14: 60 | D14: Shilpa (HNS) | E14: =E13+C14 -> 600 | F14: =960-E14 -> 360 | G14: =E14/960 -> 62.5% | H14: =IF(G14>=1, "100.0% (Package Over)", TEXT(MIN(G14*100, 99.9), "0.0") & "%") -> 62.5%
A15: 11 | B15: 06/02/2026 | C15: 60 | D15: Sneha (Foot) | E15: =E14+C15 -> 660 | F15: =960-E15 -> 300 | G15: =E15/960 -> 68.8% | H15: =IF(G15>=1, "100.0% (Package Over)", TEXT(MIN(G15*100, 99.9), "0.0") & "%") -> 68.8%
A16: 12 | B16: 08/02/2026 | C16: 60 | D16: Isha (Foot) | E16: =E15+C16 -> 720 | F16: =960-E16 -> 240 | G16: =E16/960 -> 75.0% | H16: =IF(G16>=1, "100.0% (Package Over)", TEXT(MIN(G16*100, 99.9), "0.0") & "%") -> 75.0%
A17: 13 | B17: 08/02/2026 | C17: 30 | D17: Riya (HNS) | E17: =E16+C17 -> 750 | F17: =960-E17 -> 210 | G17: =E17/960 -> 78.1% | H17: =IF(G17>=1, "100.0% (Package Over)", TEXT(MIN(G17*100, 99.9), "0.0") & "%") -> 78.1%

Sheet Sumeet
A1: CLIENT SESSION TRACKER: MR. SUMEET
A2: Start Date: 20/08/2025 | Package Details: Paid 10k for 15 hrs (900 Mins) + Paid 10k for 15k Value (01/11/25) | Total Package Capacity: 14700 Value/Mins
A4: Session No. | B4: Session Date | C4: Duration (Mins/Value) | D4: Therapist / Details | E4: Cumulative Usage | F4: Remaining Balance | G4: % Package Consumed | H4: Prob. Package Over Date
A5: 1 | B5: 20/08/2025 | C5: 90 | D5: Soma | E5: =C5 -> 90 | F5: =14700-E5 -> 14610 | G5: =E5/14700 -> 0.6% | H5: =IF(G5>=1, "100.0% (Package Over)", TEXT(MIN(G5*100, 99.9), "0.0") & "%") -> 0.6%
A6: 2 | B6: 20/08/2025 | C6: 0 | D6: Puja (90m Complementary) | E6: =E5+C6 -> 90 | F6: =14700-E6 -> 14610 | G6: =E6/14700 -> 0.6% | H6: =IF(G6>=1, "100.0% (Package Over)", TEXT(MIN(G6*100, 99.9), "0.0") & "%") -> 0.6%
A7: 3 | B7: 18/10/2025 | C7: 90 | D7: Soma | E7: =E6+C7 -> 180 | F7: =14700-E7 -> 14520 | G7: =E7/14700 -> 1.2% | H7: =IF(G7>=1, "100.0% (Package Over)", TEXT(MIN(G7*100, 99.9), "0.0") & "%") -> 1.2%
A8: 4 | B8: 18/10/2025 | C8: 90 | D8: Ritnika | E8: =E7+C8 -> 270 | F8: =14700-E8 -> 14430 | G8: =E8/14700 -> 1.8% | H8: =IF(G8>=1, "100.0% (Package Over)", TEXT(MIN(G8*100, 99.9), "0.0") & "%") -> 1.8%
A9: 5 | B9: 15/12/2025 | C9: 90 | D9: Ritnika | E9: =E8+C9 -> 360 | F9: =14700-E9 -> 14340 | G9: =E9/14700 -> 2.4% | H9: =IF(G9>=1, "100.0% (Package Over)", TEXT(MIN(G9*100, 99.9), "0.0") & "%") -> 2.4%
A10: 6 | B10: 15/12/2025 | C10: 30 | D10: Soma | E10: =E9+C10 -> 390 | F10: =14700-E10 -> 14310 | G10: =E10/14700 -> 2.7% | H10: =IF(G10>=1, "100.0% (Package Over)", TEXT(MIN(G10*100, 99.9), "0.0") & "%") -> 2.7%
A11: 7 | B11: 20/03/2026 | C11: 60 | D11: Soma | E11: =E10+C11 -> 450 | F11: =14700-E11 -> 14250 | G11: =E11/14700 -> 3.1% | H11: =IF(G11>=1, "100.0% (Package Over)", TEXT(MIN(G11*100, 99.9), "0.0") & "%") -> 3.1%
A12: 8 | B12: 20/08/2026 | C12: 60 | D12: Isha | E12: =E11+C12 -> 510 | F12: =14700-E12 -> 14190 | G12: =E12/14700 -> 3.5% | H12: =IF(G12>=1, "100.0% (Package Over)", TEXT(MIN(G12*100, 99.9), "0.0") & "%") -> 3.5%
A13: 9 | B13: 01/11/2025 | C13: 2950 | D13: Facial (Sumeet) | E13: =E12+C13 -> 3460 | F13: =14700-E13 -> 11240 | G13: =E13/14700 -> 23.5% | H13: =IF(G13>=1, "100.0% (Package Over)", TEXT(MIN(G13*100, 99.9), "0.0") & "%") -> 23.5%
A14: 10 | B14: 01/11/2025 | C14: 2950 | D14: Facial (Sumeet) | E14: =E13+C14 -> 6410 | F14: =14700-E14 -> 8290 | G14: =E14/14700 -> 43.6% | H14: =IF(G14>=1, "100.0% (Package Over)", TEXT(MIN(G14*100, 99.9), "0.0") & "%") -> 43.6%
A15: 11 | B15: 20/08/2026 | C15: 3950 | D15: Signature Facial - Daliya (Sumeet) | E15: =E14+C15 -> 10360 | F15: =14700-E15 -> 4340 | G15: =E15/14700 -> 70.5% | H15: =IF(G15>=1, "100.0% (Package Over)", TEXT(MIN(G15*100, 99.9), "0.0") & "%") -> 70.5%
A16: 12 | B16: 20/08/2026 | C16: 3950 | D16: Signature Facial - Shilpa (Sumeet) | E16: =E15+C16 -> 14310 | F16: =14700-E16 -> 390 | G16: =E16/14700 -> 97.3% | H16: =IF(G16>=1, "100.0% (Package Over)", TEXT(MIN(G16*100, 99.9), "0.0") & "%") -> 97.3%

Sheet Samapti_Roy
A1: CLIENT SESSION TRACKER: MISS SAMAPTI ROY (MERGED)
A2: Start Date: 24/08/2025 | Package Details: Paid 5k for 7 hrs + Paid 5k for 8 hrs | Total Package Capacity: 900 Mins
A4: Session No. | B4: Session Date | C4: Duration (Mins/Value) | D4: Therapist / Details | E4: Cumulative Usage | F4: Remaining Balance | G4: % Package Consumed | H4: Prob. Package Over Date
A5: 1 | B5: 24/08/2025 | C5: 60 | D5: Puja | E5: =C5 -> 60 | F5: =900-E5 -> 840 | G5: =E5/900 -> 6.7% | H5: =IF(G5>=1, "100.0% (Package Over)", TEXT(MIN(G5*100, 99.9), "0.0") & "%") -> 6.7%
A6: 2 | B6: 24/08/2025 | C6: 60 | D6: Soma | E6: =E5+C6 -> 120 | F6: =900-E6 -> 780 | G6: =E6/900 -> 13.3% | H6: =IF(G6>=1, "100.0% (Package Over)", TEXT(MIN(G6*100, 99.9), "0.0") & "%") -> 13.3%
A7: 3 | B7: 31/08/2025 | C7: 60 | D7: Soma | E7: =E6+C7 -> 180 | F7: =900-E7 -> 720 | G7: =E7/900 -> 20.0% | H7: =IF(G7>=1, "100.0% (Package Over)", TEXT(MIN(G7*100, 99.9), "0.0") & "%") -> 20.0%
A8: 4 | B8: 07/09/2025 | C8: 60 | D8: Soma | E8: =E7+C8 -> 240 | F8: =900-E8 -> 660 | G8: =E8/900 -> 26.7% | H8: =IF(G8>=1, "100.0% (Package Over)", TEXT(MIN(G8*100, 99.9), "0.0") & "%") -> 26.7%
A9: 5 | B9: 07/09/2025 | C9: 60 | D9: Suparna | E9: =E8+C9 -> 300 | F9: =900-E9 -> 600 | G9: =E9/900 -> 33.3% | H9: =IF(G9>=1, "100.0% (Package Over)", TEXT(MIN(G9*100, 99.9), "0.0") & "%") -> 33.3%
A10: 6 | B10: 23/11/2025 | C10: 60 | D10: Ritika | E10: =E9+C10 -> 360 | F10: =900-E10 -> 540 | G10: =E10/900 -> 40.0% | H10: =IF(G10>=1, "100.0% (Package Over)", TEXT(MIN(G10*100, 99.9), "0.0") & "%") -> 40.0%
A11: 7 | B11: 23/11/2025 | C11: 60 | D11: Swapna | E11: =E10+C11 -> 420 | F11: =900-E11 -> 480 | G11: =E11/900 -> 46.7% | H11: =IF(G11>=1, "100.0% (Package Over)", TEXT(MIN(G11*100, 99.9), "0.0") & "%") -> 46.7%
A12: 8 | B12: 28/12/2025 | C12: 60 | D12: Sneha (FHNS) | E12: =E11+C12 -> 480 | F12: =900-E12 -> 420 | G12: =E12/900 -> 53.3% | H12: =IF(G12>=1, "100.0% (Package Over)", TEXT(MIN(G12*100, 99.9), "0.0") & "%") -> 53.3%
A13: 9 | B13: 28/12/2025 | C13: 60 | D13: Riya (FHNS) | E13: =E12+C13 -> 540 | F13: =900-E13 -> 360 | G13: =E13/900 -> 60.0% | H13: =IF(G13>=1, "100.0% (Package Over)", TEXT(MIN(G13*100, 99.9), "0.0") & "%") -> 60.0%
A14: 10 | B14: 04/01/2026 | C14: 60 | D14: Sneha (FHNS) | E14: =E13+C14 -> 600 | F14: =900-E14 -> 300 | G14: =E14/900 -> 66.7% | H14: =IF(G14>=1, "100.0% (Package Over)", TEXT(MIN(G14*100, 99.9), "0.0") & "%") -> 66.7%
A15: 11 | B15: 04/01/2026 | C15: 60 | D15: Daliya (FHNS) | E15: =E14+C15 -> 660 | F15: =900-E15 -> 240 | G15: =E15/900 -> 73.3% | H15: =IF(G15>=1, "100.0% (Package Over)", TEXT(MIN(G15*100, 99.9), "0.0") & "%") -> 73.3%
A16: 12 | B16: 18/01/2026 | C16: 60 | D16: Riya (FHNS) | E16: =E15+C16 -> 720 | F16: =900-E16 -> 180 | G16: =E16/900 -> 80.0% | H16: =IF(G16>=1, "100.0% (Package Over)", TEXT(MIN(G16*100, 99.9), "0.0") & "%") -> 80.0%
A17: 13 | B17: 26/01/2026 | C17: 60 | D17: Riya (FHNS) | E17: =E16+C17 -> 780 | F17: =900-E17 -> 120 | G17: =E17/900 -> 86.7% | H17: =IF(G17>=1, "100.0% (Package Over)", TEXT(MIN(G17*100, 99.9), "0.0") & "%") -> 86.7%
... A19: 15 | B19: 15/02/2026 | C19: 60 | D19: Daliya (FHNS) | E19: =E18+C19 -> 900 | F19: =900-E19 -> 0 | G19: =E19/900 -> 100.0% | H19: =IF(G19>=1, "100.0% (Package Over)", TEXT(MIN(G19*100, 99.9), "0.0") & "%") -> 100.0% (Package Over)

Sheet MK_Sarkar
A1: CLIENT SESSION TRACKER: MR. M.K. SARKAR (MERGED)
A2: Start Date: 08/09/2025 | Package Details: Paid 5k for 10 hrs + Anniversary Special Offer (5k for 10 hrs) | Total Package Capacity: 1200 Mins
A4: Session No. | B4: Session Date | C4: Duration (Mins/Value) | D4: Therapist / Details | E4: Cumulative Usage | F4: Remaining Balance | G4: % Package Consumed | H4: Prob. Package Over Date
A5: 1 | B5: 08/09/2025 | C5: 60 | D5: Soma | E5: =C5 -> 60 | F5: =1200-E5 -> 1140 | G5: =E5/1200 -> 5.0% | H5: =IF(G5>=1, "100.0% (Package Over)", TEXT(MIN(G5*100, 99.9), "0.0") & "%") -> 5.0%
A6: 2 | B6: 08/10/2025 | C6: 60 | D6: Sneha | E6: =E5+C6 -> 120 | F6: =1200-E6 -> 1080 | G6: =E6/1200 -> 10.0% | H6: =IF(G6>=1, "100.0% (Package Over)", TEXT(MIN(G6*100, 99.9), "0.0") & "%") -> 10.0%
A7: 3 | B7: 31/10/2025 | C7: 60 | D7: Soma | E7: =E6+C7 -> 180 | F7: =1200-E7 -> 1020 | G7: =E7/1200 -> 15.0% | H7: =IF(G7>=1, "100.0% (Package Over)", TEXT(MIN(G7*100, 99.9), "0.0") & "%") -> 15.0%
A8: 4 | B8: 12/11/2025 | C8: 60 | D8: Swapna | E8: =E7+C8 -> 240 | F8: =1200-E8 -> 960 | G8: =E8/1200 -> 20.0% | H8: =IF(G8>=1, "100.0% (Package Over)", TEXT(MIN(G8*100, 99.9), "0.0") & "%") -> 20.0%
A9: 5 | B9: 18/11/2025 | C9: 90 | D9: Ritika | E9: =E8+C9 -> 330 | F9: =1200-E9 -> 870 | G9: =E9/1200 -> 27.5% | H9: =IF(G9>=1, "100.0% (Package Over)", TEXT(MIN(G9*100, 99.9), "0.0") & "%") -> 27.5%
A10: 6 | B10: 27/11/2025 | C10: 90 | D10: Soma | E10: =E9+C10 -> 420 | F10: =1200-E10 -> 780 | G10: =E10/1200 -> 35.0% | H10: =IF(G10>=1, "100.0% (Package Over)", TEXT(MIN(G10*100, 99.9), "0.0") & "%") -> 35.0%
A11: 7 | B11: 17/01/2026 | C11: 60 | D11: Riya | E11: =E10+C11 -> 480 | F11: =1200-E11 -> 720 | G11: =E11/1200 -> 40.0% | H11: =IF(G11>=1, "100.0% (Package Over)", TEXT(MIN(G11*100, 99.9), "0.0") & "%") -> 40.0%
A12: 8 | B12: 03/07/2026 | C12: 30 | D12: Puja (HNSF) | E12: =E11+C12 -> 510 | F12: =1200-E12 -> 690 | G12: =E12/1200 -> 42.5% | H12: =IF(G12>=1, "100.0% (Package Over)", TEXT(MIN(G12*100, 99.9), "0.0") & "%") -> 42.5%
A13: 9 | B13: 09/07/2026 | C13: 30 | D13: Puja (HNS) | E13: =E12+C13 -> 540 | F13: =1200-E13 -> 660 | G13: =E13/1200 -> 45.0% | H13: =IF(G13>=1, "100.0% (Package Over)", TEXT(MIN(G13*100, 99.9), "0.0") & "%") -> 45.0%
A14: 10 | B14: 09/07/2026 | C14: 60 | D14: Puja (Foot) | E14: =E13+C14 -> 600 | F14: =1200-E14 -> 600 | G14: =E14/1200 -> 50.0% | H14: =IF(G14>=1, "100.0% (Package Over)", TEXT(MIN(G14*100, 99.9), "0.0") & "%") -> 50.0%
A15: 11 | B15: 10/07/2026 | C15: 30 | D15: Ankit (FHNS) | E15: =E14+C15 -> 630 | F15: =1200-E15 -> 570 | G15: =E15/1200 -> 52.5% | H15: =IF(G15>=1, "100.0% (Package Over)", TEXT(MIN(G15*100, 99.9), "0.0") & "%") -> 52.5%
A16: 12 | B16: 22/07/2026 | C16: 45 | D16: Ankit (HNSB) | E16: =E15+C16 -> 675 | F16: =1200-E16 -> 525 | G16: =E16/1200 -> 56.3% | H16: =IF(G16>=1, "100.0% (Package Over)", TEXT(MIN(G16*100, 99.9), "0.0") & "%") -> 56.3%
A17: 13 | B17: 22/07/2026 | C17: 30 | D17: Puja (Foot) | E17: =E16+C17 -> 705 | F17: =1200-E17 -> 495 | G17: =E17/1200 -> 58.8% | H17: =IF(G17>=1, "100.0% (Package Over)", TEXT(MIN(G17*100, 99.9), "0.0") & "%") -> 58.8%
... A21: 17 | B21: 21/08/2026 | C21: 30 | D21: Ankit (HNSB) | E21: =E20+C21 -> 900 | F21: =1200-E21 -> 300 | G21: =E21/1200 -> 75.0% | H21: =IF(G21>=1, "100.0% (Package Over)", TEXT(MIN(G21*100, 99.9), "0.0") & "%") -> 75.0%

Sheet Komal_Sinha
A1: CLIENT SESSION TRACKER: MRS. KOMAL SINHA (POOJA OFFER)
A2: Start Date: 26/09/2025 | Package Details: Pooja Offer 5k for 6 Sessions (Total Value: 8650) | Total Package Capacity: 8650 Mins
A4: Session No. | B4: Session Date | C4: Duration (Mins/Value) | D4: Therapist / Details | E4: Cumulative Usage | F4: Remaining Balance | G4: % Package Consumed | H4: Prob. Package Over Date
A5: 1 | B5: 26/09/2025 | C5: 2200 | D5: Foot + Pedi Signature (Suparna & Soma) | E5: =C5 -> 2200 | F5: =8650-E5 -> 6450 | G5: =E5/8650 -> 25.4% | H5: =IF(G5>=1, "100.0% (Package Over)", TEXT(MIN(G5*100, 99.9), "0.0") & "%") -> 25.4%
A6: 2 | B6: 01/11/2025 | C6: 950 | D6: Soma | E6: =E5+C6 -> 3150 | F6: =8650-E6 -> 5500 | G6: =E6/8650 -> 36.4% | H6: =IF(G6>=1, "100.0% (Package Over)", TEXT(MIN(G6*100, 99.9), "0.0") & "%") -> 36.4%
A7: 3 | B7: 01/11/2025 | C7: 950 | D7: Sneha | E7: =E6+C7 -> 4100 | F7: =8650-E7 -> 4550 | G7: =E7/8650 -> 47.4% | H7: =IF(G7>=1, "100.0% (Package Over)", TEXT(MIN(G7*100, 99.9), "0.0") & "%") -> 47.4%
A8: 4 | B8: 21/02/2026 | C8: 950 | D8: Daliya | E8: =E7+C8 -> 5050 | F8: =8650-E8 -> 3600 | G8: =E8/8650 -> 58.4% | H8: =IF(G8>=1, "100.0% (Package Over)", TEXT(MIN(G8*100, 99.9), "0.0") & "%") -> 58.4%
A9: 5 | B9: 21/02/2026 | C9: 950 | D9: Sneha | E9: =E8+C9 -> 6000 | F9: =8650-E9 -> 2650 | G9: =E9/8650 -> 69.4% | H9: =IF(G9>=1, "100.0% (Package Over)", TEXT(MIN(G9*100, 99.9), "0.0") & "%") -> 69.4%
A10: 6 | B10: 21/02/2026 | C10: 950 | D10: Session 6 | E10: =E9+C10 -> 6950 | F10: =8650-E10 -> 1700 | G10: =E10/8650 -> 80.3% | H10: =IF(G10>=1, "100.0% (Package Over)", TEXT(MIN(G10*100, 99.9), "0.0") & "%") -> 80.3%
A11: 7 | B11: 21/02/2026 | C11: 950 | D11: Session 7 | E11: =E10+C11 -> 7900 | F11: =8650-E11 -> 750 | G11: =E11/8650 -> 91.3% | H11: =IF(G11>=1, "100.0% (Package Over)", TEXT(MIN(G11*100, 99.9), "0.0") & "%") -> 91.3%
A12: 8 | B12: 21/02/2026 | C12: 750 | D12: 1 Deluxe Manicure (Complimentary) | E12: =E11+C12 -> 8650 | F12: =8650-E12 -> 0 | G12: =E12/8650 -> 100.0% | H12: =IF(G12>=1, "100.0% (Package Over)", TEXT(MIN(G12*100, 99.9), "0.0") & "%") -> 100.0% (Package Over)

Sheet J_Mehta
A1: CLIENT SESSION TRACKER: J. MEHTA (9830111676)
A2: Start Date: 08/10/2025 | Package Details: Paid 10k for 14 hrs (840 Mins) | Phone: 9830111676 | Total Package Capacity: 840 Mins
A4: Session No. | B4: Session Date | C4: Duration (Mins/Value) | D4: Therapist / Details | E4: Cumulative Usage | F4: Remaining Balance | G4: % Package Consumed | H4: Prob. Package Over Date
